# 一、异常

## （一）产生异常

- Java 内部错误发生异常，Java 虚拟机产生的异常。

- 编写的程序代码中的错误所产生的异常，例如空指针异常、数组越界异常等。
- 通过 throw 语句手动生成的异常，一般用来告知该方法的调用者一些必要信息。

> **把生成异常对象，并把它提交给运行时系统的过程称为拋出（throw）异常。**
>
> **运行时系统在方法的调用栈中查找，直到找到能够处理该类型异常的对象，这一个过程称为捕获（catch）异常。**



## （二）异常分类

**在 Java 中所有异常类型都是内置类 java.lang.Throwable 类的子类**

### 1. 异常 Exception

Exception 类用于用户程序可能出现的异常情况，它也是用来创建自定义异常类型类的类。

#### （1）运行时异常（RuntimeException）

- NullPropagation：空指针异常；
- ClassCastException：类型强制转换异常
- IllegalArgumentException：传递非法参数异常
- IndexOutOfBoundsException：下标越界异常
- NumberFormatException：数字格式异常

#### （2）非运行时异常

- ClassNotFoundException：找不到指定 class 的异常
- IOException：IO 操作异常

### 2. 错误 Error 

Error 定义了在通常环境下不希望被程序捕获的异常。一般指的是 JVM 错误，如堆栈溢出。

- OutOfMemoryError：内存溢出异常
- NoClassDefFoundError：找不到 class 定义异常
- StackOverflowError：深递归导致栈被耗尽而抛出的异常

![image-20211208132659856](https://raw.githubusercontent.com/LSC-cong/Bolg/main/cloudimages/202112081326947.png)

## （三）异常处理

1. try catch 语句用于捕获并处理异常，catch 语句可以有多个，用来匹配多个异常
2. 除特殊情况外如：在 try 块、catch 块中调用了退出虚拟机的方法`System.exit(int status)`，否则finally 语句的代码在任何情况下都必须执行；
3. throw 语句用于拋出异常，throws 语句用于声明可能会出现的异常。
4. 使用try-catch-finally语句时，只有 try 块是必需的，catch 块和 finally 块都是可选的，但 catch 块和 finally 块至少出现其中之一，也可以同时出现；

```java
try {
    // 可能会发生异常的语句
} catch(ExceptionType e) {
    // 处理异常语句
} catch(ExceptionType e) {
    // 处理异常语句
} catch(ExceptionType e) {
    // 处理异常语句
...
} finally {
    // 清理代码块
}
```

**注意有return时，语句执行顺序的变化：**

​		当程序执行try{}遇到return时，程序会先执行return语句，但并不会立即返回——也就是把return语句要做的一切事情都准备好，也就是在将要返回、但并未返回的时候，程序把执行流程转去执行finally块，当finally块执行完成后就直接返回刚才return语句已经准备好的结果。

**（1）finally块中的return会覆盖try块中的return**

```java
public class FinallyTest2 {
    public static void main(String []args){
        System.out.println(test2());
    }
    private static int test2() {
        int b = 20;
        try {
            System.out.println("try语句块");
            return b+=80;
        }catch (Exception e){
            System.out.println("catch语句块");
        }finally {
            System.out.println("finally语句块");
            if (b>25){
                System.out.println("b>25,b="+b);
            }
            return 200;
        }
    }
}
/*
try语句块
finally语句块
b>25,b=100
200
*/
```
**（2）finally中没有return，原来的返回值变不变说不准**

> 代码1中finally的“干扰”没有起作用，代码2中finally的map.put(“key”,“finally”);起作用了，但是map=null并没起到作用。这里涉及到的就是java到底是传值还是传址了。简单来讲，java只有传值，没有传址，所以map=null；没有起作用。

```java
public class FinallyTest3 {
    public static void main(String []args){
        System.out.println(test3());
    }

    private static int test3() {
        int b = 20;
        try {
            System.out.println("try语句块");
            return b+=80;
        }catch (Exception e){
            System.out.println("catch语句块");
        }finally {
            System.out.println("finally语句块");
            if (b>25){
                System.out.println("b>25,b="+b);
            }
            b=150;
        }
        return 2000;
    }
}
/*
try语句块
finally语句块
b>25,b=100
100
*/
//========================================================================//
public class FinallyTest4 {
    public static void main(String []args){
        System.out.println(getMap().get("key").toString());
    }
    public static Map<String,String> getMap(){
        HashMap<String, String> map = new HashMap<>();
        map.put("key","init");

        try {
            map.put("key","try");
            return map;
        }catch (Exception e){
            map.put("key","catch");
        }finally {
            map.put("key","finally");
            map=null;
        }
        return map;
    }
}
//finally
```



（3）异常发生，try块中的return不会执行

```java
public class FinallyTest5 {
    public static void main(String []args){
        System.out.println(test5());
    }
    private static int test5() {
        int b = 20;
        try {
            System.out.println("try语句块");
            b=b/0;//异常
            return b+=80;
        }catch (Exception e){
            b+=15;
            System.out.println("catch语句块");
        }finally {
            System.out.println("finally语句块");
            if (b>25){
                System.out.println("b>25,b="+b);
            }
            b+=50;
        }
        return b;
    }
}
/*
try语句块
catch语句块
finally语句块
b>25,b=35
85
*/
```

（4）异常发生，catch中的return执行情况和未发生异常的try中return执行情况一样

```java
public class FinallyTest6 {
    public static void main(String []args){
        System.out.println(test6());
    }

    private static int test6() {
        int b = 20;
        try {
            System.out.println("try语句块");
            b=b/0;
            return b+=80;
        }catch (Exception e){
            System.out.println("catch语句块");
            return b+=15;
        }finally {
            System.out.println("finally语句块");
            if (b>25){
                System.out.println("b>25,b="+b);
            }
            b+=50;
        }
    }
}
/*
try语句块
catch语句块
finally语句块
b>25,b=35
35
*/
```



## （四）throws和throw抛出异常

- throws 用来声明一个方法可能抛出的所有异常信息，表示出现异常的一种可能性，但并不一定会发生这些异常；throw 则是指拋出的一个具体的异常类型，执行 throw 则一定抛出了某种异常对象。
- 通常在一个方法（类）的声明处通过 throws 声明方法（类）可能拋出的异常信息，而在方法（类）内部通过 throw 声明一个具体的异常信息。
- throws 通常不用显示地捕获异常，可由系统自动将所有捕获的异常信息抛给上级方法； throw 则需要用户自己捕获相关的异常，而后再对其进行相关包装，最后将包装后的异常信息抛出。

# 二、断言和日志
